{
 "cells": [
  {
   "cell_type": "markdown",
   "metadata": {},
   "source": [
    "# Manejo de Excepciones en Python"
   ]
  },
  {
   "cell_type": "markdown",
   "metadata": {},
   "source": [
    "## Introducción a las Excepciones\n",
    "\n",
    "En el desarrollo de software, es común encontrarse con situaciones donde el flujo normal de ejecución de un programa se ve interrumpido debido a condiciones excepcionales. Estas condiciones, conocidas como excepciones, pueden surgir por diversos motivos, como errores de entrada, problemas de recursos o fallos en la lógica del programa. Python proporciona un mecanismo robusto para manejar estas situaciones a través de su sistema de manejo de excepciones.\n",
    "\n",
    "## Concepto de Excepciones\n",
    "\n",
    "Una excepción en Python es un objeto que representa un error que ocurre durante la ejecución del programa. Cuando se produce una excepción, el flujo normal del programa se interrumpe y Python busca un manejador de excepciones apropiado para tratar la situación.\n",
    "\n"
   ]
  },
  {
   "cell_type": "markdown",
   "metadata": {},
   "source": [
    "## Tipos Comunes de Excepciones\n",
    "\n",
    "Python define una jerarquía de excepciones, cada una correspondiente a diferentes tipos de errores. Algunas de las excepciones más comunes incluyen:\n",
    "\n",
    "1. **ValueError**: Se produce cuando una función recibe un argumento del tipo correcto pero con un valor inapropiado.\n",
    "2. **TypeError**: Ocurre cuando se intenta realizar una operación en un objeto de tipo inapropiado.\n",
    "3. **IndexError**: Se genera al intentar acceder a un índice que está fuera del rango de una secuencia.\n",
    "4. **KeyError**: Surge cuando se intenta acceder a una clave que no existe en un diccionario.\n",
    "5. **FileNotFoundError**: Se produce cuando se intenta abrir un archivo que no existe.\n",
    "\n",
    "## Estructura del Manejo de Excepciones\n",
    "\n",
    "Python utiliza las palabras clave `try`, `except`, `else`, y `finally` para estructurar el manejo de excepciones.\n",
    "\n",
    "### Bloque try-except\n",
    "\n",
    "La estructura básica para el manejo de excepciones en Python es el bloque `try-except`:\n",
    "\n",
    "```python\n",
    "try:\n",
    "    # Código que puede generar una excepción\n",
    "    resultado = operacion_riesgosa()\n",
    "except TipoDeExcepcion:\n",
    "    # Código para manejar la excepción\n",
    "    manejar_error()\n",
    "```\n",
    "\n",
    "El código dentro del bloque `try` se ejecuta normalmente. Si se produce una excepción, el flujo de ejecución se transfiere inmediatamente al bloque `except` correspondiente.\n",
    "\n",
    "### Manejo de Múltiples Excepciones\n",
    "\n",
    "Es posible manejar múltiples tipos de excepciones en un solo bloque `try`:\n",
    "\n",
    "```python\n",
    "try:\n",
    "    numero = int(input(\"Ingrese un número: \"))\n",
    "    resultado = 10 / numero\n",
    "except ValueError:\n",
    "    print(\"Error: Ingrese un número válido.\")\n",
    "except ZeroDivisionError:\n",
    "    print(\"Error: No se puede dividir por cero.\")\n",
    "```\n",
    "\n",
    "### Cláusula else\n",
    "\n",
    "La cláusula `else` se ejecuta si no se produce ninguna excepción en el bloque `try`:\n",
    "\n",
    "```python\n",
    "try:\n",
    "    archivo = open(\"datos.txt\", \"r\")\n",
    "except FileNotFoundError:\n",
    "    print(\"El archivo no existe.\")\n",
    "else:\n",
    "    contenido = archivo.read()\n",
    "    archivo.close()\n",
    "```\n",
    "\n",
    "### Cláusula finally\n",
    "\n",
    "La cláusula `finally` se ejecuta siempre, independientemente de si se produjo una excepción o no:\n",
    "\n",
    "```python\n",
    "try:\n",
    "    archivo = open(\"datos.txt\", \"r\")\n",
    "except FileNotFoundError:\n",
    "    print(\"El archivo no existe.\")\n",
    "else:\n",
    "    contenido = archivo.read()\n",
    "finally:\n",
    "    archivo.close()\n",
    "```\n",
    "\n",
    "## Buenas Prácticas en el Manejo de Excepciones\n",
    "\n",
    "1. **Especificidad**: Capture excepciones específicas en lugar de utilizar una captura genérica de `Exception`.\n",
    "2. **Alcance limitado**: Mantenga los bloques `try` lo más pequeños posible para aislar el código propenso a errores.\n",
    "3. **Información de diagnóstico**: Proporcione información útil al manejar excepciones para facilitar la depuración.\n",
    "4. **Evite el silenciamiento**: No capture excepciones sin proporcionar un manejo adecuado.\n",
    "\n",
    "## Creación de Excepciones Personalizadas\n",
    "\n",
    "Python permite la definición de excepciones personalizadas mediante la creación de nuevas clases que hereden de `Exception`:\n",
    "\n",
    "```python\n",
    "class MiErrorPersonalizado(Exception):\n",
    "    def __init__(self, mensaje):\n",
    "        self.mensaje = mensaje\n",
    "\n",
    "    def __str__(self):\n",
    "        return f\"Se produjo un error personalizado: {self.mensaje}\"\n",
    "\n",
    "try:\n",
    "    raise MiErrorPersonalizado(\"Este es un error específico de mi aplicación\")\n",
    "except MiErrorPersonalizado as e:\n",
    "    print(e)\n",
    "```\n",
    "\n",
    "## Conclusión\n",
    "\n",
    "El manejo efectivo de excepciones es una habilidad crucial en la programación con Python. Permite crear software más robusto y resistente a fallos, mejorando la experiencia del usuario y facilitando el mantenimiento del código. Al comprender y aplicar adecuadamente los conceptos y técnicas presentados en este capítulo, los desarrolladores pueden escribir programas que manejen situaciones excepcionales de manera elegante y controlada."
   ]
  },
  {
   "cell_type": "markdown",
   "metadata": {},
   "source": [
    "## Tipos Comunes de Excepciones en Python\n",
    "\n",
    "En Python, las excepciones son eventos que interrumpen el flujo normal de ejecución de un programa cuando ocurre un error. Existen muchos tipos de excepciones que cubren una amplia variedad de errores posibles. A continuación, se presentan algunas de las excepciones más comunes que es importante conocer:\n",
    "\n",
    "### ZeroDivisionError\n",
    "\n",
    "Esta excepción ocurre cuando se intenta dividir un número por cero, lo cual es una operación matemáticamente indefinida. Por ejemplo:\n",
    "\n",
    "```python\n",
    "resultado = 10 / 0  # Esto genera un ZeroDivisionError\n",
    "```\n",
    "\n",
    "### NameError\n",
    "\n",
    "Un `NameError` se produce cuando se intenta acceder a una variable o nombre que no ha sido definido previamente en el entorno actual. Esto sucede, por ejemplo, si escribes mal el nombre de una variable o intentas usar una variable antes de definirla:\n",
    "\n",
    "```python\n",
    "print(mi_variable)  # Esto genera un NameError porque 'mi_variable' no está definida\n",
    "```\n",
    "\n",
    "### TypeError\n",
    "\n",
    "Un `TypeError` se lanza cuando se intenta realizar una operación en un tipo de dato inapropiado. Esto puede ocurrir, por ejemplo, al intentar sumar un número y una cadena de texto:\n",
    "\n",
    "```python\n",
    "resultado = \"3\" + 3  # Esto genera un TypeError porque no puedes sumar una cadena y un entero\n",
    "```\n",
    "\n",
    "### ValueError\n",
    "\n",
    "El `ValueError` ocurre cuando una función recibe un argumento del tipo correcto pero con un valor inapropiado. Un caso común es intentar convertir una cadena que no representa un número en un entero:\n",
    "\n",
    "```python\n",
    "numero = int(\"abc\")  # Esto genera un ValueError porque 'abc' no se puede convertir en un entero\n",
    "```\n",
    "\n",
    "### IndexError\n",
    "\n",
    "El `IndexError` aparece cuando se intenta acceder a un índice que está fuera del rango válido en una lista, tupla u otra estructura de secuencia:\n",
    "\n",
    "```python\n",
    "lista = [1, 2, 3]\n",
    "print(lista[5])  # Esto genera un IndexError porque no hay un índice 5 en la lista\n",
    "```\n",
    "\n",
    "### KeyError\n",
    "\n",
    "Un `KeyError` se produce cuando se intenta acceder a una clave que no existe en un diccionario. Esto es común cuando se asume incorrectamente que una clave está presente en un diccionario:\n",
    "\n",
    "```python\n",
    "diccionario = {\"a\": 1, \"b\": 2}\n",
    "print(diccionario[\"c\"])  # Esto genera un KeyError porque la clave 'c' no está en el diccionario\n",
    "```\n",
    "\n",
    "### FileNotFoundError\n",
    "\n",
    "Esta excepción ocurre cuando se intenta abrir un archivo que no existe en el sistema. Es común cuando se especifica una ruta de archivo incorrecta o el archivo ha sido movido o eliminado:\n",
    "\n",
    "```python\n",
    "archivo = open(\"archivo_inexistente.txt\", \"r\")  # Esto genera un FileNotFoundError\n",
    "```\n",
    "\n",
    "### IOError\n",
    "\n",
    "Un `IOError` (Input/Output Error) se lanza cuando ocurre un problema durante una operación de entrada/salida, como leer o escribir en un archivo. Esto puede ocurrir por problemas con el archivo, permisos, o si el dispositivo de almacenamiento no está disponible:\n",
    "\n",
    "```python\n",
    "with open(\"archivo.txt\", \"r\") as archivo:\n",
    "    contenido = archivo.read()  # Puede generar un IOError si ocurre un problema al leer el archivo\n",
    "```\n",
    "\n",
    "### ImportError\n",
    "\n",
    "Un `ImportError` ocurre cuando se intenta importar un módulo que no se encuentra disponible en el entorno de Python, ya sea porque el nombre del módulo es incorrecto o el módulo no está instalado:\n",
    "\n",
    "```python\n",
    "import modulo_inexistente  # Esto genera un ImportError porque el módulo no existe\n",
    "```\n",
    "\n",
    "### KeyboardInterrupt\n",
    "\n",
    "El `KeyboardInterrupt` es una excepción especial que se lanza cuando el usuario interrumpe la ejecución de un programa manualmente, generalmente utilizando la combinación de teclas `Ctrl + C`. Esta excepción es útil para permitir que un programa realice operaciones de limpieza antes de finalizar:\n",
    "\n",
    "```python\n",
    "while True:\n",
    "    try:\n",
    "        print(\"Ejecutando... Presiona Ctrl+C para interrumpir.\")\n",
    "    except KeyboardInterrupt:\n",
    "        print(\"Ejecución interrumpida por el usuario.\")\n",
    "        break\n",
    "```\n",
    "\n",
    "### AttributeError\n",
    "\n",
    "Un `AttributeError` se produce cuando se intenta acceder o asignar un atributo que no existe en un objeto. Esto puede ocurrir si se confunde el tipo de un objeto o si se intenta usar un atributo que no está definido en la clase del objeto:\n",
    "\n",
    "```python\n",
    "cadena = \"Hola\"\n",
    "cadena.append(\"!\")  # Esto genera un AttributeError porque las cadenas no tienen el método 'append'\n",
    "```\n",
    "\n",
    "### Conclusión\n",
    "\n",
    "Conocer y entender los diferentes tipos de excepciones en Python es crucial para escribir código robusto y resistente a errores. Al saber qué excepciones son comunes y por qué ocurren, puedes manejar estos errores de manera más efectiva, asegurando que tu programa pueda responder adecuadamente a situaciones inesperadas. Cada una de estas excepciones ofrece una pista sobre lo que ha salido mal en tu código, y manejarlas correctamente puede hacer que tus programas sean más estables y profesionales."
   ]
  },
  {
   "cell_type": "markdown",
   "metadata": {},
   "source": [
    "## Cláusulas `else` y `finally` en el Manejo de Excepciones en Python\n",
    "\n",
    "En Python, el manejo de excepciones se realiza comúnmente mediante los bloques `try` y `except`, que permiten capturar y manejar errores que ocurren durante la ejecución de un programa. Sin embargo, Python ofrece dos herramientas adicionales que son muy útiles para controlar el flujo de ejecución en presencia de excepciones: las cláusulas `else` y `finally`. Estas cláusulas proporcionan una manera más precisa y expresiva de manejar situaciones excepcionales y asegurar que ciertas operaciones se realicen, independientemente de los errores que puedan ocurrir.\n",
    "\n",
    "### La Cláusula `else`\n",
    "\n",
    "La cláusula `else` en el manejo de excepciones se utiliza para ejecutar un bloque de código si y solo si no se produce ninguna excepción en el bloque `try`. Esto significa que el código dentro del bloque `else` se ejecutará únicamente cuando el código dentro del `try` se ejecute sin problemas.\n",
    "\n",
    "El uso de `else` es particularmente útil cuando tienes operaciones que solo deben realizarse si no ocurre ningún error en el bloque `try`. Al utilizar `else`, puedes mantener el manejo de excepciones separado del código que debe ejecutarse cuando no hay errores, lo que mejora la legibilidad y estructura de tu programa.\n",
    "\n",
    "**Ejemplo de uso de `else`:**\n",
    "\n",
    "```python\n",
    "try:\n",
    "    # Intentamos convertir la entrada en un número\n",
    "    numero = int(input(\"Introduce un número: \"))\n",
    "except ValueError as error:\n",
    "    # Este bloque captura un ValueError si la conversión falla\n",
    "    print(\"Ingrese un valor que corresponda. Ha ocurrido un error de tipo:\", error)\n",
    "else:\n",
    "    # Este bloque se ejecuta solo si no se produjo ninguna excepción en el bloque `try`\n",
    "    print(\"El número ingresado es:\", numero)\n",
    "```\n",
    "\n",
    "En este ejemplo, si el usuario ingresa un valor que no puede ser convertido a un número, el programa captura el `ValueError` y muestra un mensaje de error. Si no ocurre ninguna excepción, el bloque `else` se ejecuta, mostrando el número ingresado. Esto permite que las operaciones que dependen del éxito del bloque `try` se mantengan separadas y claras.\n",
    "\n",
    "### La Cláusula `finally`\n",
    "\n",
    "La cláusula `finally` se utiliza para definir un bloque de código que se ejecutará siempre, independientemente de si ocurrió o no una excepción en el bloque `try`. Esto es especialmente útil para realizar tareas que deben ejecutarse sin importar si el código tuvo éxito o falló, como liberar recursos, cerrar archivos, o desconectar una base de datos.\n",
    "\n",
    "El bloque `finally` garantiza que se ejecutará en cualquier circunstancia, lo que asegura que se completen ciertas operaciones críticas para el estado o limpieza del sistema, incluso si se produce un error.\n",
    "\n",
    "**Ejemplo de uso de `finally`:**\n",
    "\n",
    "```python\n",
    "try:\n",
    "    # Intentamos convertir la entrada en un número\n",
    "    numero = int(input(\"Introduce un número: \"))\n",
    "except ValueError as error:\n",
    "    # Captura el ValueError si la conversión falla\n",
    "    print(\"Ingrese un valor que corresponda. Ha ocurrido un error de tipo:\", error)\n",
    "finally:\n",
    "    # Este bloque se ejecuta siempre, ocurra o no una excepción\n",
    "    print(\"El programa ha finalizado\")\n",
    "```\n",
    "\n",
    "En este ejemplo, si el usuario ingresa un valor incorrecto, se captura la excepción y se muestra un mensaje de error. Después, el bloque `finally` se ejecuta, mostrando \"El programa ha finalizado\" independientemente de si hubo o no un error. Esto asegura que el programa siempre realice esta última acción.\n",
    "\n",
    "### Combinación de `else` y `finally`\n",
    "\n",
    "Es posible utilizar `else` y `finally` juntos en un bloque de manejo de excepciones para tener un control completo sobre lo que sucede en diferentes escenarios. Esto permite manejar errores específicos, ejecutar código solo si no hay errores, y asegurarse de que ciertas operaciones se realicen siempre.\n",
    "\n",
    "**Ejemplo completo:**\n",
    "\n",
    "```python\n",
    "try:\n",
    "    numero = int(input(\"Introduce un número: \"))\n",
    "except ValueError as error:\n",
    "    # Captura un error específico, en este caso un ValueError\n",
    "    print(\"Ingrese un valor que corresponda. Ha ocurrido un error de tipo:\", error)\n",
    "else:\n",
    "    # Se ejecuta solo si no hay excepciones\n",
    "    print(\"El número ingresado es:\", numero)\n",
    "finally:\n",
    "    # Se ejecuta siempre, independientemente de si hubo o no una excepción\n",
    "    print(\"El programa ha finalizado\")\n",
    "```\n",
    "\n",
    "En este ejemplo:\n",
    "\n",
    "- **`try`**: Intenta ejecutar código que puede fallar.\n",
    "- **`except`**: Captura y maneja errores específicos.\n",
    "- **`else`**: Ejecuta código si no hubo errores en el `try`.\n",
    "- **`finally`**: Ejecuta código siempre, asegurando que ciertas acciones se realicen sin importar el resultado del `try`.\n",
    "\n",
    "### Conclusión\n",
    "\n",
    "Las cláusulas `else` y `finally` en Python son herramientas poderosas que permiten manejar excepciones de manera más controlada y eficiente. La cláusula `else` proporciona un lugar específico para el código que solo debe ejecutarse cuando no hay errores, mientras que la cláusula `finally` asegura que ciertas operaciones se realicen siempre, independientemente de lo que ocurra en el bloque `try`. Al combinar estas herramientas, puedes escribir código más robusto, legible y fácil de mantener."
   ]
  },
  {
   "cell_type": "markdown",
   "metadata": {},
   "source": [
    "## Invocación Manual de Excepciones en Python\n",
    "\n",
    "En Python, las excepciones son una herramienta esencial para manejar errores y situaciones inesperadas que pueden ocurrir durante la ejecución de un programa. Mientras que las excepciones generalmente se generan automáticamente cuando ocurre un error, Python también te permite invocar manualmente una excepción utilizando la instrucción `raise`. Esta capacidad es poderosa, ya que te permite forzar un error bajo condiciones específicas, proporcionando un mayor control sobre cómo se manejan las situaciones excepcionales en tu código.\n",
    "\n",
    "### ¿Qué es `raise` y Cuándo Usarlo?\n",
    "\n",
    "La instrucción `raise` se utiliza para lanzar una excepción de manera explícita. Esto significa que puedes generar una excepción en cualquier momento de la ejecución de tu programa, no solo cuando ocurre un error de forma natural. La sintaxis básica para usar `raise` es la siguiente:\n",
    "\n",
    "```python\n",
    "raise TipoDeExcepción(\"Mensaje de error\")\n",
    "```\n",
    "\n",
    "- **`TipoDeExcepción`**: Es el tipo de excepción que deseas invocar, como `ValueError`, `TypeError`, o `ZeroDivisionError`.\n",
    "- **`Mensaje de error`**: Es un mensaje opcional que describe el error y que se mostrará cuando se lance la excepción. Este mensaje ayuda a entender mejor la causa del error cuando se captura y se maneja la excepción.\n",
    "\n",
    "### ¿Por Qué Invocar Excepciones Manualmente?\n",
    "\n",
    "Invocar excepciones manualmente es útil en varias situaciones:\n",
    "\n",
    "1. **Validación de Datos**: Si estás validando datos y encuentras que no cumplen con ciertos criterios, puedes lanzar una excepción para detener la ejecución y manejar la situación adecuadamente.\n",
    "  \n",
    "2. **Pruebas y Debugging**: Durante las pruebas, puedes forzar la aparición de un error para ver cómo responde tu programa, asegurándote de que las excepciones se manejan correctamente.\n",
    "\n",
    "3. **Prevención de Errores Graves**: Si sabes que cierta condición en tu código provocará un error grave si se permite continuar, puedes lanzar una excepción para detener el proceso y evitar consecuencias negativas.\n",
    "\n",
    "### Ejemplo Práctico: Lanzando una Excepción con `raise`\n",
    "\n",
    "Consideremos el siguiente ejemplo de una función de división. Normalmente, dividir un número por cero en Python genera automáticamente una excepción `ZeroDivisionError`. Sin embargo, en este caso, queremos detectar esta condición y lanzar la excepción manualmente con un mensaje personalizado.\n",
    "\n",
    "```python\n",
    "def division(n=0):\n",
    "    if n == 0:\n",
    "        raise ZeroDivisionError(\"No se puede dividir por cero\", f\"El valor de n es {n}\")\n",
    "    return 5 / n\n",
    "```\n",
    "\n",
    "En esta función:\n",
    "\n",
    "- **Comprobación del Divisor**: Antes de realizar la división, la función comprueba si el valor de `n` es cero. Si lo es, se lanza una excepción `ZeroDivisionError` con un mensaje que explica que no se puede dividir por cero y proporciona el valor que causó el problema.\n",
    "- **Lanzamiento de la Excepción**: La instrucción `raise` se utiliza para generar esta excepción de manera explícita.\n",
    "\n",
    "### Manejo de la Excepción\n",
    "\n",
    "Una vez que se lanza una excepción, podemos capturarla y manejarla usando un bloque `try-except`. Esto permite que el programa reaccione de manera controlada al error y realice acciones específicas en respuesta.\n",
    "\n",
    "```python\n",
    "try:\n",
    "    division()  # Intenta ejecutar la función `division` con el valor predeterminado de `n`, que es 0\n",
    "except ZeroDivisionError as error:\n",
    "    print(\"Ocurrió un error:\", error)\n",
    "```\n",
    "\n",
    "En este ejemplo:\n",
    "\n",
    "- **Captura de la Excepción**: La función `division()` se llama con su valor predeterminado, que es 0. Esto provoca que se lance la `ZeroDivisionError`.\n",
    "- **Manejo de la Excepción**: El bloque `except` captura la excepción y muestra el mensaje de error definido en la función `division`.\n",
    "\n",
    "### Consideraciones Importantes\n",
    "\n",
    "Aunque `raise` es una herramienta poderosa, es importante usarla de manera responsable:\n",
    "\n",
    "1. **No Invocar Excepciones Sin Razón Justificada**: Lanza excepciones manualmente solo cuando sea necesario, como en casos de validación de datos críticos o para prevenir errores graves.\n",
    "\n",
    "2. **Impacto en el Rendimiento**: Las excepciones son costosas en términos de rendimiento, por lo que no deben utilizarse para controlar el flujo normal de un programa. En su lugar, reserva `raise` para situaciones donde realmente se necesita detener la ejecución o manejar un error grave.\n",
    "\n",
    "### Conclusión\n",
    "\n",
    "Invocar excepciones manualmente en Python utilizando `raise` te proporciona un control adicional sobre cómo y cuándo se manejan los errores en tu programa. Al usar esta herramienta de manera adecuada, puedes mejorar la robustez y la seguridad de tu código, asegurando que las situaciones problemáticas se identifiquen y manejen de manera apropiada. Sin embargo, es fundamental utilizar `raise` de manera justificada, para no afectar negativamente el rendimiento o la claridad de tu programa."
   ]
  },
  {
   "cell_type": "markdown",
   "metadata": {},
   "source": [
    "## Excepciones Personalizadas en Python\n",
    "\n",
    "En Python, las excepciones son una herramienta esencial para manejar errores y situaciones inesperadas que pueden ocurrir durante la ejecución de un programa. Aunque Python proporciona una amplia gama de excepciones integradas, como `ValueError`, `TypeError`, y `ZeroDivisionError`, a veces puede ser útil crear tus propias excepciones personalizadas. Estas excepciones personalizadas te permiten capturar y manejar errores específicos de tu aplicación, proporcionando mensajes de error claros y específicos que facilitan la identificación y resolución de problemas.\n",
    "\n",
    "### ¿Qué son las Excepciones Personalizadas?\n",
    "\n",
    "Las excepciones personalizadas son clases que defines tú mismo y que heredan de la clase base `Exception`. Al crear una excepción personalizada, puedes añadir tus propios atributos y métodos, y proporcionar mensajes de error que sean más descriptivos y útiles para tu aplicación específica.\n",
    "\n",
    "Por ejemplo, si estás desarrollando una aplicación de cálculo y quieres manejar de manera especial la división por cero, puedes crear una excepción personalizada que incluya un mensaje claro y un código de error que te ayude a identificar rápidamente la causa del problema.\n",
    "\n",
    "### Cómo Crear una Excepción Personalizada\n",
    "\n",
    "Para crear una excepción personalizada en Python, sigues estos pasos:\n",
    "\n",
    "1. Define una nueva clase que herede de `Exception`.\n",
    "2. Añade un constructor (`__init__`) para inicializar cualquier atributo que desees (por ejemplo, un mensaje y un código de error).\n",
    "3. (Opcional) Define un método `__str__` para devolver una representación en cadena del objeto de la excepción.\n",
    "\n",
    "Aquí tienes un ejemplo de cómo crear una excepción personalizada:\n",
    "\n",
    "```python\n",
    "class MiError(Exception):\n",
    "    \"\"\"\n",
    "    Esta clase define una excepción personalizada llamada `MiError`. \n",
    "    Se utiliza para representar errores específicos en tu programa.\n",
    "    \"\"\"\n",
    "\n",
    "    def __init__(self, mensaje, codigo):\n",
    "        \"\"\"\n",
    "        Inicializa la excepción con un mensaje y un código de error.\n",
    "        - `mensaje`: Describe el error que ha ocurrido.\n",
    "        - `codigo`: Un código de error que ayuda a identificar el tipo de problema.\n",
    "        \"\"\"\n",
    "        self.mensaje = mensaje\n",
    "        self.codigo = codigo\n",
    "\n",
    "    def __str__(self):\n",
    "        \"\"\"\n",
    "        Devuelve una representación en cadena del objeto de la excepción.\n",
    "        \"\"\"\n",
    "        return f\"MiError: {self.mensaje} - código: {self.codigo}\"\n",
    "```\n",
    "\n",
    "### ¿Cómo Usar una Excepción Personalizada?\n",
    "\n",
    "Una vez que has definido tu excepción personalizada, puedes utilizarla en tu código de la misma manera que utilizarías cualquier otra excepción. Por ejemplo, podrías lanzarla cuando detectas una condición específica que indica un error en tu aplicación.\n",
    "\n",
    "Supongamos que quieres utilizar esta excepción en una función que realiza una división. Si el divisor es cero, lanzas tu excepción personalizada:\n",
    "\n",
    "```python\n",
    "def division(n=0):\n",
    "    if n == 0:\n",
    "        # Si `n` es cero, lanzamos una excepción personalizada `MiError`.\n",
    "        raise MiError(\"No se puede dividir por cero\", 404)\n",
    "    return 5 / n\n",
    "```\n",
    "\n",
    "En este ejemplo:\n",
    "\n",
    "- Si `n` es cero, la función lanza una excepción `MiError` con un mensaje y un código de error personalizados.\n",
    "- Si `n` no es cero, la función realiza la división normalmente.\n",
    "\n",
    "### Capturar y Manejar Excepciones Personalizadas\n",
    "\n",
    "Al igual que con las excepciones integradas de Python, puedes capturar y manejar tus excepciones personalizadas utilizando un bloque `try-except`. Esto te permite controlar cómo responde tu programa cuando ocurre un error.\n",
    "\n",
    "```python\n",
    "try:\n",
    "    division()  # Intenta ejecutar la función `division` con el valor predeterminado de `n`, que es 0\n",
    "except MiError as error:\n",
    "    # Captura la excepción personalizada `MiError` y maneja el error.\n",
    "    print(\"Ocurrió un error:\", error)\n",
    "```\n",
    "\n",
    "En este bloque de código:\n",
    "\n",
    "- Llamamos a la función `division()` sin pasar un valor para `n`, por lo que utiliza el valor predeterminado de 0.\n",
    "- Esto lanza la excepción `MiError`, que es capturada por el bloque `except`.\n",
    "- El bloque `except` muestra el mensaje de error y el código de error definidos en la excepción.\n",
    "\n",
    "### Beneficios de Usar Excepciones Personalizadas\n",
    "\n",
    "Crear y utilizar excepciones personalizadas en Python tiene varios beneficios:\n",
    "\n",
    "1. **Claridad**: Proporcionas mensajes de error específicos que hacen que sea más fácil entender qué salió mal.\n",
    "2. **Especificidad**: Puedes capturar y manejar errores de manera más precisa, respondiendo de manera adecuada a diferentes tipos de problemas.\n",
    "3. **Facilidad de Mantenimiento**: Los códigos de error y los mensajes personalizados facilitan el diagnóstico y la resolución de problemas, lo que resulta en un código más fácil de mantener y depurar.\n",
    "\n",
    "### Conclusión\n",
    "\n",
    "Las excepciones personalizadas en Python son una herramienta poderosa que te permite manejar errores de manera específica y controlada. Al definir tus propias excepciones, puedes proporcionar información adicional sobre los errores, como mensajes personalizados y códigos de error, que facilitan la depuración y el mantenimiento de tu código. Aprender a crear y manejar excepciones personalizadas te permitirá escribir programas más robustos y adaptados a las necesidades específicas de tu aplicación."
   ]
  },
  {
   "cell_type": "markdown",
   "metadata": {},
   "source": [
    "# Exception Hierarchy\n",
    "\n",
    "The class hierarchy for built-in exceptions is:\n",
    "\n",
    "```\n",
    "BaseException\n",
    " ├── BaseExceptionGroup\n",
    " ├── GeneratorExit\n",
    " ├── KeyboardInterrupt\n",
    " ├── SystemExit\n",
    " └── Exception\n",
    "      ├── ArithmeticError\n",
    "      │    ├── FloatingPointError\n",
    "      │    ├── OverflowError\n",
    "      │    └── ZeroDivisionError\n",
    "      ├── AssertionError\n",
    "      ├── AttributeError\n",
    "      ├── BufferError\n",
    "      ├── EOFError\n",
    "      ├── ExceptionGroup [BaseExceptionGroup]\n",
    "      ├── ImportError\n",
    "      │    └── ModuleNotFoundError\n",
    "      ├── LookupError\n",
    "      │    ├── IndexError\n",
    "      │    └── KeyError\n",
    "      ├── MemoryError\n",
    "      ├── NameError\n",
    "      │    └── UnboundLocalError\n",
    "      ├── OSError\n",
    "      │    ├── BlockingIOError\n",
    "      │    ├── ChildProcessError\n",
    "      │    ├── ConnectionError\n",
    "      │    │    ├── BrokenPipeError\n",
    "      │    │    ├── ConnectionAbortedError\n",
    "      │    │    ├── ConnectionRefusedError\n",
    "      │    │    └── ConnectionResetError\n",
    "      │    ├── FileExistsError\n",
    "      │    ├── FileNotFoundError\n",
    "      │    ├── InterruptedError\n",
    "      │    ├── IsADirectoryError\n",
    "      │    ├── NotADirectoryError\n",
    "      │    ├── PermissionError\n",
    "      │    ├── ProcessLookupError\n",
    "      │    └── TimeoutError\n",
    "      ├── ReferenceError\n",
    "      ├── RuntimeError\n",
    "      │    ├── NotImplementedError\n",
    "      │    └── RecursionError\n",
    "      ├── StopAsyncIteration\n",
    "      ├── StopIteration\n",
    "      ├── SyntaxError\n",
    "      │    └── IndentationError\n",
    "      │         └── TabError\n",
    "      ├── SystemError\n",
    "      ├── TypeError\n",
    "      ├── ValueError\n",
    "      │    └── UnicodeError\n",
    "      │         ├── UnicodeDecodeError\n",
    "      │         ├── UnicodeEncodeError\n",
    "      │         └── UnicodeTranslateError\n",
    "      └── Warning\n",
    "           ├── BytesWarning\n",
    "           ├── DeprecationWarning\n",
    "           ├── EncodingWarning\n",
    "           ├── FutureWarning\n",
    "           ├── ImportWarning\n",
    "           ├── PendingDeprecationWarning\n",
    "           ├── ResourceWarning\n",
    "           ├── RuntimeWarning\n",
    "           ├── SyntaxWarning\n",
    "           ├── UnicodeWarning\n",
    "           └── UserWarning\n",
    "```"
   ]
  },
  {
   "cell_type": "markdown",
   "metadata": {},
   "source": []
  }
 ],
 "metadata": {
  "language_info": {
   "name": "python"
  }
 },
 "nbformat": 4,
 "nbformat_minor": 2
}
